#VRML_SIM R2020a utf8
WorldInfo {
  basicTimeStep 16
}
Viewpoint {
  orientation -0.3630078331149632 0.9022837511967091 0.23261415568183683 2.9368136604645514
  position 0.5965869098989118 5.2458031549470086 -9.307952200168836
}
TexturedBackground {
}
TexturedBackgroundLight {
}
E-puck {
  translation 0.3 0 0.31
  controller "EPuckAvoideCollision"
}
Floor {
}
Robot {
  translation -0.1 0.1 -0.21
  children [
    DEF Body Shape {
      appearance PBRAppearance {
        baseColor 1 0 0
        metalness 0
      }
      geometry Box {
        size 0.1 0.05 0.2
      }
    }
    HingeJoint {
      jointParameters HingeJointParameters {
        anchor 0.06 0 0.05
      }
      device [
        RotationalMotor {
          name "wheel1"
        }
      ]
      endPoint DEF wheel1 Solid {
        translation 0.06 0 0.05
        rotation 1.5707179855829958e-16 7.853589927914979e-17 1 1.57
        children [
          DEF Wheel Shape {
            appearance PBRAppearance {
              baseColor 0 1 0
              metalness 0
            }
            geometry Cylinder {
              height 0.02
              radius 0.04
            }
          }
        ]
        name "wheel1"
        boundingObject USE Wheel
        physics DEF Wheel_Ph Physics {
        }
      }
    }
    HingeJoint {
      jointParameters HingeJointParameters {
        anchor -0.06 0 0.05
      }
      device [
        RotationalMotor {
          name "wheel2"
        }
      ]
      endPoint DEF wheel2 Solid {
        translation -0.06 0 0.05
        rotation 0 0 1 1.57
        children [
          USE Wheel
        ]
        name "wheel2"
        boundingObject USE Wheel
        physics USE Wheel_Ph
      }
    }
    HingeJoint {
      jointParameters HingeJointParameters {
        anchor 0.06 0 -0.05
      }
      device [
        RotationalMotor {
          name "wheel3"
        }
      ]
      endPoint DEF wheel3 Solid {
        translation 0.06 0 -0.05
        rotation 0 -7.853589927914979e-17 1 1.5700000000000003
        children [
          USE Wheel
        ]
        name "wheel3"
        boundingObject USE Wheel
        physics USE Wheel_Ph
      }
    }
    HingeJoint {
      jointParameters HingeJointParameters {
        anchor -0.06 0 -0.05
      }
      device [
        RotationalMotor {
          name "wheel4"
        }
      ]
      endPoint DEF wheel4 Solid {
        translation -0.06 0 -0.05
        rotation 2.356076978374494e-16 0 1 1.57
        children [
          USE Wheel
        ]
        name "wheel4"
        boundingObject USE Wheel
        physics USE Wheel_Ph
      }
    }
    DistanceSensor {
      translation -0.02 0 0.1
      rotation 0 1 0 -1.87
      children [
        DEF sensor Shape {
          appearance PBRAppearance {
          }
          geometry DEF Sensor Box {
            size 0.01 0.01 0.01
          }
        }
      ]
      name "ds_right"
    }
    DistanceSensor {
      translation 0.02 0 0.1
      rotation 0 1 0 -1.27
      children [
        USE sensor
      ]
      name "ds_left"
    }
  ]
  name "Robot"
  boundingObject USE Body
  physics Physics {
  }
  controller "Robot_controller"
}
FourWheelsRobot {
}
GammaTug {
  controller "Gamma_controller"
}
